2025-02-12 01:35:25,777 - __main__ - DEBUG - 入力ファイル: D:\BMS\document\tech_docs\tools\The_Duolingo_Handbook.pdf
2025-02-12 01:35:25,778 - __main__ - DEBUG - ファイル拡張子: .pdf
2025-02-12 01:35:25,778 - __main__ - DEBUG - 変換処理開始: _convert_pdf
2025-02-12 01:35:25,779 - __main__ - DEBUG - PDFの変換開始
2025-02-12 01:35:25,908 - __main__ - DEBUG - ページ 1 の処理中
2025-02-12 01:35:26,529 - __main__ - DEBUG - ページ 2 の処理中
2025-02-12 01:35:26,577 - __main__ - DEBUG - ページ 3 の処理中
2025-02-12 01:35:26,593 - __main__ - DEBUG - ページ 4 の処理中
2025-02-12 01:35:26,609 - __main__ - DEBUG - ページ 5 の処理中
2025-02-12 01:35:26,715 - __main__ - DEBUG - ページ 6 の処理中
2025-02-12 01:35:26,733 - __main__ - DEBUG - ページ 7 の処理中
2025-02-12 01:35:30,035 - __main__ - DEBUG - ページ 8 の処理中
2025-02-12 01:35:33,044 - __main__ - DEBUG - ページ 9 の処理中
2025-02-12 01:35:35,360 - __main__ - DEBUG - ページ 10 の処理中
2025-02-12 01:35:35,375 - __main__ - DEBUG - ページ 11 の処理中
2025-02-12 01:35:36,671 - __main__ - DEBUG - ページ 12 の処理中
2025-02-12 01:35:36,681 - __main__ - DEBUG - ページ 13 の処理中
2025-02-12 01:35:36,687 - __main__ - DEBUG - ページ 14 の処理中
2025-02-12 01:35:36,700 - __main__ - DEBUG - ページ 15 の処理中
2025-02-12 01:35:37,946 - __main__ - DEBUG - ページ 16 の処理中
2025-02-12 01:35:38,033 - __main__ - DEBUG - ページ 17 の処理中
2025-02-12 01:35:39,877 - __main__ - DEBUG - ページ 18 の処理中
2025-02-12 01:35:39,883 - __main__ - DEBUG - ページ 19 の処理中
2025-02-12 01:35:41,751 - __main__ - DEBUG - ページ 20 の処理中
2025-02-12 01:35:43,737 - __main__ - DEBUG - ページ 21 の処理中
2025-02-12 01:35:47,517 - __main__ - DEBUG - ページ 22 の処理中
2025-02-12 01:35:47,608 - __main__ - DEBUG - ページ 23 の処理中
2025-02-12 01:35:52,540 - __main__ - DEBUG - ページ 24 の処理中
2025-02-12 01:35:55,699 - __main__ - DEBUG - ページ 25 の処理中
2025-02-12 01:35:58,543 - __main__ - DEBUG - ページ 26 の処理中
2025-02-12 01:35:58,563 - __main__ - DEBUG - ページ 27 の処理中
2025-02-12 01:36:01,766 - __main__ - DEBUG - ページ 28 の処理中
2025-02-12 01:36:04,682 - __main__ - DEBUG - ページ 29 の処理中
2025-02-12 01:36:04,715 - __main__ - DEBUG - ページ 30 の処理中
2025-02-12 01:36:04,739 - __main__ - DEBUG - ページ 31 の処理中
2025-02-12 01:36:04,772 - __main__ - DEBUG - ページ 32 の処理中
2025-02-12 01:36:04,886 - __main__ - DEBUG - ページ 33 の処理中
2025-02-12 01:36:04,991 - __main__ - DEBUG - ページ 34 の処理中
2025-02-12 01:36:05,024 - __main__ - DEBUG - ページ 35 の処理中
2025-02-12 01:36:05,073 - __main__ - DEBUG - PDFの変換完了
2025-02-12 01:36:05,073 - __main__ - DEBUG - 変換処理完了
2025-02-12 01:36:05,074 - __main__ - DEBUG - 保存先: D:\BMS\tools\markitdown\output\The_Duolingo_Handbook_20250212_013605.md
2025-02-12 01:36:05,081 - __main__ - DEBUG - 保存完了
2025-02-20 00:55:15,909 - __main__ - DEBUG - 入力ファイル: D:\BMS\tools\ai_agent_rule.md
2025-02-20 00:55:15,910 - __main__ - DEBUG - ファイル拡張子: .md
2025-02-20 00:55:15,911 - __main__ - DEBUG - 変換処理開始: _convert_markdown
2025-02-20 00:55:15,912 - __main__ - DEBUG - Markdownファイルの読み込み
2025-02-20 00:55:15,913 - __main__ - DEBUG - 変換処理完了
2025-02-20 00:55:15,915 - __main__ - DEBUG - 保存先: D:\BMS\tools\markitdown\output\ai_agent_rule_20250220_005515.md
2025-02-20 00:55:15,919 - __main__ - DEBUG - 保存完了
2025-02-20 00:56:04,619 - __main__ - DEBUG - 入力ファイル: D:\BMS\document\papers\money\tax_all.pdf
2025-02-20 00:56:04,620 - __main__ - DEBUG - ファイル拡張子: .pdf
2025-02-20 00:56:04,620 - __main__ - DEBUG - 変換処理開始: _convert_pdf
2025-02-20 00:56:04,621 - __main__ - DEBUG - PDFの変換開始
2025-02-20 00:56:04,698 - __main__ - ERROR - PDF処理エラー: PyCryptodome is required for AES algorithm
2025-02-20 00:56:04,699 - __main__ - ERROR - 詳細なエラー情報:
Traceback (most recent call last):
  File "D:\BMS\tools\markitdown\markitdown.py", line 228, in _convert_pdf
    reader = PdfReader(str(file_path))
             ^^^^^^^^^^^^^^^^^^^^^^^^^
  File "C:\Users\3836\AppData\Local\Packages\PythonSoftwareFoundation.Python.3.12_qbz5n2kfra8p0\LocalCache\local-packages\Python312\site-packages\PyPDF2\_reader.py", line 339, in __init__
    self._encryption.verify(pwd) == PasswordType.NOT_DECRYPTED
    ^^^^^^^^^^^^^^^^^^^^^^^^^^^^
  File "C:\Users\3836\AppData\Local\Packages\PythonSoftwareFoundation.Python.3.12_qbz5n2kfra8p0\LocalCache\local-packages\Python312\site-packages\PyPDF2\_encryption.py", line 785, in verify
    key, rc = self.verify_v4(pwd) if self.algV <= 4 else self.verify_v5(pwd)
                                                         ^^^^^^^^^^^^^^^^^^^
  File "C:\Users\3836\AppData\Local\Packages\PythonSoftwareFoundation.Python.3.12_qbz5n2kfra8p0\LocalCache\local-packages\Python312\site-packages\PyPDF2\_encryption.py", line 836, in verify_v5
    key = AlgV5.verify_owner_password(
          ^^^^^^^^^^^^^^^^^^^^^^^^^^^^
  File "C:\Users\3836\AppData\Local\Packages\PythonSoftwareFoundation.Python.3.12_qbz5n2kfra8p0\LocalCache\local-packages\Python312\site-packages\PyPDF2\_encryption.py", line 530, in verify_owner_password
    AlgV5.calculate_hash(R, password, o_value[32:40], u_value[:48])
  File "C:\Users\3836\AppData\Local\Packages\PythonSoftwareFoundation.Python.3.12_qbz5n2kfra8p0\LocalCache\local-packages\Python312\site-packages\PyPDF2\_encryption.py", line 561, in calculate_hash
    E = AES_CBC_encrypt(K[:16], K[16:32], K1 * 64)
        ^^^^^^^^^^^^^^^^^^^^^^^^^^^^^^^^^^^^^^^^^^
  File "C:\Users\3836\AppData\Local\Packages\PythonSoftwareFoundation.Python.3.12_qbz5n2kfra8p0\LocalCache\local-packages\Python312\site-packages\PyPDF2\_encryption.py", line 162, in AES_CBC_encrypt
    raise DependencyError("PyCryptodome is required for AES algorithm")
PyPDF2.errors.DependencyError: PyCryptodome is required for AES algorithm
2025-02-20 00:56:04,710 - __main__ - ERROR - エラー発生: PyCryptodome is required for AES algorithm
2025-02-20 00:56:04,711 - __main__ - ERROR - 詳細なエラー情報:
Traceback (most recent call last):
  File "D:\BMS\tools\markitdown\markitdown.py", line 105, in convert
    result = converter(file_path)
             ^^^^^^^^^^^^^^^^^^^^
  File "D:\BMS\tools\markitdown\markitdown.py", line 228, in _convert_pdf
    reader = PdfReader(str(file_path))
             ^^^^^^^^^^^^^^^^^^^^^^^^^
  File "C:\Users\3836\AppData\Local\Packages\PythonSoftwareFoundation.Python.3.12_qbz5n2kfra8p0\LocalCache\local-packages\Python312\site-packages\PyPDF2\_reader.py", line 339, in __init__
    self._encryption.verify(pwd) == PasswordType.NOT_DECRYPTED
    ^^^^^^^^^^^^^^^^^^^^^^^^^^^^
  File "C:\Users\3836\AppData\Local\Packages\PythonSoftwareFoundation.Python.3.12_qbz5n2kfra8p0\LocalCache\local-packages\Python312\site-packages\PyPDF2\_encryption.py", line 785, in verify
    key, rc = self.verify_v4(pwd) if self.algV <= 4 else self.verify_v5(pwd)
                                                         ^^^^^^^^^^^^^^^^^^^
  File "C:\Users\3836\AppData\Local\Packages\PythonSoftwareFoundation.Python.3.12_qbz5n2kfra8p0\LocalCache\local-packages\Python312\site-packages\PyPDF2\_encryption.py", line 836, in verify_v5
    key = AlgV5.verify_owner_password(
          ^^^^^^^^^^^^^^^^^^^^^^^^^^^^
  File "C:\Users\3836\AppData\Local\Packages\PythonSoftwareFoundation.Python.3.12_qbz5n2kfra8p0\LocalCache\local-packages\Python312\site-packages\PyPDF2\_encryption.py", line 530, in verify_owner_password
    AlgV5.calculate_hash(R, password, o_value[32:40], u_value[:48])
  File "C:\Users\3836\AppData\Local\Packages\PythonSoftwareFoundation.Python.3.12_qbz5n2kfra8p0\LocalCache\local-packages\Python312\site-packages\PyPDF2\_encryption.py", line 561, in calculate_hash
    E = AES_CBC_encrypt(K[:16], K[16:32], K1 * 64)
        ^^^^^^^^^^^^^^^^^^^^^^^^^^^^^^^^^^^^^^^^^^
  File "C:\Users\3836\AppData\Local\Packages\PythonSoftwareFoundation.Python.3.12_qbz5n2kfra8p0\LocalCache\local-packages\Python312\site-packages\PyPDF2\_encryption.py", line 162, in AES_CBC_encrypt
    raise DependencyError("PyCryptodome is required for AES algorithm")
PyPDF2.errors.DependencyError: PyCryptodome is required for AES algorithm
2025-02-20 00:56:52,655 - __main__ - DEBUG - 入力ファイル: D:\BMS\document\papers\money\tax_all.pdf
2025-02-20 00:56:52,657 - __main__ - DEBUG - ファイル拡張子: .pdf
2025-02-20 00:56:52,657 - __main__ - DEBUG - 変換処理開始: _convert_pdf
2025-02-20 00:56:52,657 - __main__ - DEBUG - PDFの変換開始
2025-02-20 00:56:52,723 - __main__ - ERROR - PDF処理エラー: PyCryptodome is required for AES algorithm
2025-02-20 00:56:52,724 - __main__ - ERROR - 詳細なエラー情報:
Traceback (most recent call last):
  File "D:\BMS\tools\markitdown\markitdown.py", line 228, in _convert_pdf
    reader = PdfReader(str(file_path))
             ^^^^^^^^^^^^^^^^^^^^^^^^^
  File "C:\Users\3836\AppData\Local\Packages\PythonSoftwareFoundation.Python.3.12_qbz5n2kfra8p0\LocalCache\local-packages\Python312\site-packages\PyPDF2\_reader.py", line 339, in __init__
    self._encryption.verify(pwd) == PasswordType.NOT_DECRYPTED
    ^^^^^^^^^^^^^^^^^^^^^^^^^^^^
  File "C:\Users\3836\AppData\Local\Packages\PythonSoftwareFoundation.Python.3.12_qbz5n2kfra8p0\LocalCache\local-packages\Python312\site-packages\PyPDF2\_encryption.py", line 785, in verify
    key, rc = self.verify_v4(pwd) if self.algV <= 4 else self.verify_v5(pwd)
                                                         ^^^^^^^^^^^^^^^^^^^
  File "C:\Users\3836\AppData\Local\Packages\PythonSoftwareFoundation.Python.3.12_qbz5n2kfra8p0\LocalCache\local-packages\Python312\site-packages\PyPDF2\_encryption.py", line 836, in verify_v5
    key = AlgV5.verify_owner_password(
          ^^^^^^^^^^^^^^^^^^^^^^^^^^^^
  File "C:\Users\3836\AppData\Local\Packages\PythonSoftwareFoundation.Python.3.12_qbz5n2kfra8p0\LocalCache\local-packages\Python312\site-packages\PyPDF2\_encryption.py", line 530, in verify_owner_password
    AlgV5.calculate_hash(R, password, o_value[32:40], u_value[:48])
  File "C:\Users\3836\AppData\Local\Packages\PythonSoftwareFoundation.Python.3.12_qbz5n2kfra8p0\LocalCache\local-packages\Python312\site-packages\PyPDF2\_encryption.py", line 561, in calculate_hash
    E = AES_CBC_encrypt(K[:16], K[16:32], K1 * 64)
        ^^^^^^^^^^^^^^^^^^^^^^^^^^^^^^^^^^^^^^^^^^
  File "C:\Users\3836\AppData\Local\Packages\PythonSoftwareFoundation.Python.3.12_qbz5n2kfra8p0\LocalCache\local-packages\Python312\site-packages\PyPDF2\_encryption.py", line 162, in AES_CBC_encrypt
    raise DependencyError("PyCryptodome is required for AES algorithm")
PyPDF2.errors.DependencyError: PyCryptodome is required for AES algorithm
2025-02-20 00:56:52,735 - __main__ - ERROR - エラー発生: PyCryptodome is required for AES algorithm
2025-02-20 00:56:52,736 - __main__ - ERROR - 詳細なエラー情報:
Traceback (most recent call last):
  File "D:\BMS\tools\markitdown\markitdown.py", line 105, in convert
    result = converter(file_path)
             ^^^^^^^^^^^^^^^^^^^^
  File "D:\BMS\tools\markitdown\markitdown.py", line 228, in _convert_pdf
    reader = PdfReader(str(file_path))
             ^^^^^^^^^^^^^^^^^^^^^^^^^
  File "C:\Users\3836\AppData\Local\Packages\PythonSoftwareFoundation.Python.3.12_qbz5n2kfra8p0\LocalCache\local-packages\Python312\site-packages\PyPDF2\_reader.py", line 339, in __init__
    self._encryption.verify(pwd) == PasswordType.NOT_DECRYPTED
    ^^^^^^^^^^^^^^^^^^^^^^^^^^^^
  File "C:\Users\3836\AppData\Local\Packages\PythonSoftwareFoundation.Python.3.12_qbz5n2kfra8p0\LocalCache\local-packages\Python312\site-packages\PyPDF2\_encryption.py", line 785, in verify
    key, rc = self.verify_v4(pwd) if self.algV <= 4 else self.verify_v5(pwd)
                                                         ^^^^^^^^^^^^^^^^^^^
  File "C:\Users\3836\AppData\Local\Packages\PythonSoftwareFoundation.Python.3.12_qbz5n2kfra8p0\LocalCache\local-packages\Python312\site-packages\PyPDF2\_encryption.py", line 836, in verify_v5
    key = AlgV5.verify_owner_password(
          ^^^^^^^^^^^^^^^^^^^^^^^^^^^^
  File "C:\Users\3836\AppData\Local\Packages\PythonSoftwareFoundation.Python.3.12_qbz5n2kfra8p0\LocalCache\local-packages\Python312\site-packages\PyPDF2\_encryption.py", line 530, in verify_owner_password
    AlgV5.calculate_hash(R, password, o_value[32:40], u_value[:48])
  File "C:\Users\3836\AppData\Local\Packages\PythonSoftwareFoundation.Python.3.12_qbz5n2kfra8p0\LocalCache\local-packages\Python312\site-packages\PyPDF2\_encryption.py", line 561, in calculate_hash
    E = AES_CBC_encrypt(K[:16], K[16:32], K1 * 64)
        ^^^^^^^^^^^^^^^^^^^^^^^^^^^^^^^^^^^^^^^^^^
  File "C:\Users\3836\AppData\Local\Packages\PythonSoftwareFoundation.Python.3.12_qbz5n2kfra8p0\LocalCache\local-packages\Python312\site-packages\PyPDF2\_encryption.py", line 162, in AES_CBC_encrypt
    raise DependencyError("PyCryptodome is required for AES algorithm")
PyPDF2.errors.DependencyError: PyCryptodome is required for AES algorithm
